<?xml version="1.0"?>
<!-- =================================================================================== -->
<!-- |    This document was autogenerated by xacro from model/two-link.xacro           | -->
<!-- |    EDITING THIS FILE BY HAND IS NOT RECOMMENDED                                 | -->
<!-- =================================================================================== -->
<robot name="two_link_manipulator">
    <!--LINKS-->
    <link name="world"/>
    <link name="base_link">
        <visual>
            <origin rpy="0 0 0" xyz="0 0 0.5"/>
            <geometry>
                <box size="0.2 0.2 1"/>
            </geometry>
        </visual>
        <collision>
            <origin rpy="0 0 0" xyz="0 0 0.5"/>
            <geometry>
                <box size="0.2 0.2 1"/>
            </geometry>
        </collision>
        <inertial>
            <origin rpy="0 0 0" xyz="0 0 0.5"/>
            <mass value="1"/>
            <inertia ixx="1.0" ixy="0.0" ixz="0.0" iyy="1.0" iyz="0.0" izz="1.0"/>
        </inertial>
    </link>
    <link name="link1">
        <visual>
            <origin rpy="0 0 0" xyz="0 0 0.3"/>
            <geometry>
                <box size="0.05 0.05 0.6"/>
            </geometry>
        </visual>
        <collision>
            <origin rpy="0 0 0" xyz="0 0 0.3"/>
            <geometry>
                <box size="0.05 0.05 0.6"/>
            </geometry>
        </collision>
        <inertial>
            <origin rpy="0 0 0" xyz="0 0 0.3"/>
            <mass value="1"/>
            <inertia ixx="1.0" ixy="0.0" ixz="0.0" iyy="1.0" iyz="0.0" izz="1.0"/>
        </inertial>
    </link>
    <link name="link2">
        <visual>
            <origin rpy="0 0 0" xyz="0 0 0.1625"/>
            <geometry>
                <box size="0.05 0.05 0.375"/>
            </geometry>
        </visual>
        <collision>
            <origin rpy="0 0 0" xyz="0 0 0.1625"/>
            <geometry>
                <box size="0.05 0.05 0.375"/>
            </geometry>
        </collision>
        <inertial>
            <origin rpy="0 0 0" xyz="0 0 0.1625"/>
            <mass value="1"/>
            <inertia ixx="1.0" ixy="0.0" ixz="0.0" iyy="1.0" iyz="0.0" izz="1.0"/>
        </inertial>
    </link>
    <!--JOINTS-->
    <joint name="base_world" type="fixed">
        <origin rpy="0 0 0" xyz="0 0 0"/>
        <parent link="world"/>
        <child link="base_link"/>
    </joint>
    <joint name="joint1" type="revolute">
        <origin rpy="0 1.5707963267948966 0" xyz="0 0.125 0.95"/>
        <parent link="base_link"/>
        <child link="link1"/>
        <axis xyz="0 1 0"/>
        <limit effort="100" lower="-1000" upper="1000" velocity="1"/>
        <dynamics damping="0" friction="0"/>
    </joint>
    <joint name="joint2" type="revolute">
        <origin rpy="0 0 0" xyz="0 0.05 0.575"/>
        <parent link="link1"/>
        <child link="link2"/>
        <axis xyz="0 1 0"/>
        <limit effort="100" lower="-1000" upper="1000" velocity="1"/>
        <dynamics damping="0" friction="0"/>
    </joint>
    <transmission name="trans_joint1">
        <type>
            transmission_interface/SimpleTransmission
        </type>
        <joint name="joint1">
            <hardwareInterface>
                hardware_interface/EffortJointInterface
            </hardwareInterface>
        </joint>
        <actuator name="motor_joint1">
            <hardwareInterface>
                hardware_interface/EffortJointInterface
            </hardwareInterface>
            <mechanicalReduction>
                1
            </mechanicalReduction>
        </actuator>
    </transmission>
    <transmission name="trans_joint2">
        <type>
            transmission_interface/SimpleTransmission
        </type>
        <joint name="joint2">
            <hardwareInterface>
                hardware_interface/EffortJointInterface
            </hardwareInterface>
        </joint>
        <actuator name="motor_joint2">
            <hardwareInterface>
                hardware_interface/EffortJointInterface
            </hardwareInterface>
            <mechanicalReduction>
                1
            </mechanicalReduction>
        </actuator>
    </transmission>
    <gazebo reference="base_link">
        <material>Gazebo/White</material>
    </gazebo>
    <gazebo reference="link1">
        <material>Gazebo/Orange</material>
    </gazebo>
    <gazebo reference="link2">
        <material>Gazebo/White</material>
    </gazebo>
    <gazebo>
        <plugin filename="libgazebo_ros_control.so" name="gazebo_ros_control"/>
    </gazebo>
</robot>